Workbook
Name VALOR_CONCLUIDO: '9. Conciliación'!$I$16

Sheet Portada
A10: OPINIÓN DE VALOR COMERCIAL
A12: =IF('2. Antecedentes'!E13="","",'2. Antecedentes'!E13&IF('2. Antecedentes'!Q11<>""," en "&LOWER('2. Antecedentes'!Q11),""))
A15: FOTOGRAFÍA PRINCIPAL DEL INMUEBLE
A28: FOLIO | E28: =IF('2. Antecedentes'!Q9="","",'2. Antecedentes'!Q9)
A29: FECHA DE VALUACIÓN | E29: =IF('2. Antecedentes'!Q10="","",'2. Antecedentes'!Q10)
A30: SOLICITANTE | E30: =IF('2. Antecedentes'!E10="","",'2. Antecedentes'!E10)
A31: PROPIETARIO DEL INMUEBLE | E31: =IF('2. Antecedentes'!E12="","",'2. Antecedentes'!E12)
A32: INMUEBLE QUE SE VALÚA | E32: =IF('2. Antecedentes'!E13="","",'2. Antecedentes'!E13)
A33: UBICACIÓN DEL INMUEBLE | E33: =IF('2. Antecedentes'!E17="","",'2. Antecedentes'!E17)
A34: PROPÓSITO DE LA OPINIÓN DE VALOR | E34: =IF('2. Antecedentes'!E22="","",'2. Antecedentes'!E22)
A36: VALOR COMERCIAL CONCLUIDO | E36: =IF(ISNUMBER('9. Conciliación'!I16),'9. Conciliación'!I16,"Pendiente") -> Pendiente
A38: =IF(ISNUMBER('9. Conciliación'!I16),"("&'9. Conciliación'!Q26&")","")
A40: Opinión comercial orientativa. No es precio de venta garantizado. Todos los resultados se expresan en MXN.
A42: ="" -> BORRADOR: documento en elaboración, sin validez para el cliente

Sheet Índice
I2: ="Opinión de valor comercial"&IF('2. Antecedentes'!$Q$9<>"",CHAR(10)&"Folio "&'2. Antecedentes'!$Q$9,"") -> Opinión de valor comercial
A7: ÍNDICE | N7: GUÍA DE CAPTURA
A9: 1 | B9: Resumen ejecutivo
A10: 2 | B10: Antecedentes | N10: 1. Guarda una copia por inmueble
A11: 3 | B11: Características urbanas de la zona | N11: Usa el folio del expediente. Conserva este archivo sin datos de clientes.
A12: 4 | B12: Características del inmueble
A13: 5 | B13: Enfoque comparativo de mercado: terrenos
A14: 6 | B14: Enfoque comparativo de mercado: inmuebles construidos
A15: 7 | B15: Enfoque de ingresos (capitalización de rentas) | N15: 2. Completa Antecedentes
A16: 8 | B16: Enfoque físico (valor neto de reposición) | N16: Captura campos del informe y panel desde columna N. Azul claro = entrada; fórmulas = resultados.
A17: 9 | B17: Conciliación de valor y justificación
A18: 10 | B18: Reporte fotográfico del inmueble
N20: 3. Documenta inmueble y zona
N21: Reutiliza 04, 05 y 06. Marca origen de cada dato. No repitas levantamientos ni supongas que una restricción está resuelta.
B22: Las secciones 5 a 8 se aplican según el tipo de inmueble y la evidencia disponible. Un enfoque con peso de 0 % no participa en la conciliación y su exclusión se justifica en la sección 9.
N25: 4. Elige fuentes y enfoques
N26: En Mercado e Ingresos completa las fichas desde N10. Incluye solo fuentes elegidas y justificadas. Tres completas habilitan la media.
N30: 5. Revisa y concluye
N31: En Conciliación asigna pesos, escribe conclusión, elige redondeo y registra revisión. El valor queda pendiente si faltan bases.
N40: 7. Prepara la entrega
N41: El área de impresión A:L contiene el informe. La captura lateral no se imprime. Si un enfoque se excluye, explica la razón; al exportar puedes seleccionar solo las hojas aplicables. Revisa índice y PDF.
N45: 8. Cambios y cancelaciones
N46: Marca cancelación o cambio de operación en Antecedentes. Al cambiar datos incrementa versión, actualiza fuentes y repite revisión. La aprobación de la plantilla no aprueba una valoración real.

Sheet 1. Resumen
I2: ="Opinión de valor comercial"&IF('2. Antecedentes'!$Q$9<>"",CHAR(10)&"Folio "&'2. Antecedentes'!$Q$9,"") -> Opinión de valor comercial
A7: 1. RESUMEN EJECUTIVO
A9: DATOS GENERALES
A10: Solicitante | D10: =IF('2. Antecedentes'!E10="","",'2. Antecedentes'!E10)
A11: Tipo de inmueble | D11: =IF('2. Antecedentes'!E13="","",'2. Antecedentes'!E13)
A12: Ubicación | D12: =IF('2. Antecedentes'!E17="","",'2. Antecedentes'!E17)
A13: Régimen de propiedad | D13: =IF('2. Antecedentes'!E15="","",'2. Antecedentes'!E15)
A14: Cuenta catastral | D14: =IF('2. Antecedentes'!E16="","",'2. Antecedentes'!E16) | G14: Folio | I14: =IF('2. Antecedentes'!Q9="","",'2. Antecedentes'!Q9)
A15: Superficie de terreno | D15: =IF('4. Inmueble'!D10="","",'4. Inmueble'!D10) | G15: Sup. construida | I15: =IF('4. Inmueble'!D19="","",'4. Inmueble'!D19)
A17: CARACTERÍSTICAS PRINCIPALES
A18: Niveles | D18: =IF('4. Inmueble'!I19="","",'4. Inmueble'!I19) | G18: Edad (años) | I18: =IF('4. Inmueble'!I21="","",'4. Inmueble'!I21)
A19: Recámaras | D19: =IF('4. Inmueble'!D20="","",'4. Inmueble'!D20) | G19: Baños | I19: =IF('4. Inmueble'!I20="","",'4. Inmueble'!I20)
A20: Estado de conservación | D20: =IF('4. Inmueble'!D22="","",'4. Inmueble'!D22) | G20: Estacionamientos | I20: =IF('4. Inmueble'!D21="","",'4. Inmueble'!D21)
A22: RESULTADOS POR ENFOQUE DE VALOR
A23: Enfoque | H23: Peso | J23: Valor indicado
A24: Comparativo de mercado | H24: =IF('9. Conciliación'!D11="","",'9. Conciliación'!D11) | J24: =IF('9. Conciliación'!F11="","",'9. Conciliación'!F11)
A25: Ingresos (capitalización) | H25: =IF('9. Conciliación'!D12="","",'9. Conciliación'!D12) | J25: =IF('9. Conciliación'!F12="","",'9. Conciliación'!F12)
A26: Físico (neto de reposición) | H26: =IF('9. Conciliación'!D13="","",'9. Conciliación'!D13) | J26: =IF('9. Conciliación'!F13="","",'9. Conciliación'!F13)
A27: VALOR COMERCIAL CONCLUIDO | H27: =IF(ISNUMBER('9. Conciliación'!I16),'9. Conciliación'!I16,"Pendiente") -> Pendiente
A28: =IF('9. Conciliación'!Q26="","","("&'9. Conciliación'!Q26&")")
A29: OBSERVACIONES Y CONCLUSIÓN
A30: =IF('9. Conciliación'!A19="","",'9. Conciliación'!A19)
A38: VIGENCIA DE LA OPINIÓN
A39: =IF(ISNUMBER('2. Antecedentes'!E26),"Esta opinión es válida hasta el "&TEXT('2. Antecedentes'!E26,"dd \d\e mmmm \d\e yyyy")&", salvo cambios en el inmueble, la operación o las condiciones de mercado.","")

Sheet 2. Antecedentes
I2: ="Opinión de valor comercial"&IF('2. Antecedentes'!$Q$9<>"",CHAR(10)&"Folio "&'2. Antecedentes'!$Q$9,"") -> Opinión de valor comercial
A7: 2. ANTECEDENTES | N7: DATOS DE CONTROL (captura)
A9: DE LA SOLICITUD | N9: Folio único
A10: Solicitante | N10: Fecha de valor
A11: Relación del solicitante con el inmueble | N11: Operación | Q11: Venta
A12: Propietario del inmueble | N12: Estado | Q12: En estudio
A13: Inmueble objeto de la opinión | N13: Base de mercado
A14: Uso o destino actual | N14: Versión del informe | Q14: 1
A15: Régimen de propiedad | N15: Moneda de resultados | Q15: MXN
A16: Cuenta catastral | N16: MXN por 1 USD
A17: Ubicación del inmueble | N17: Fecha de conversión
A18: Fecha de solicitud | N18: Fuente de conversión
N19: Inspección
A20: DE LA OPINIÓN DE VALOR | N20: Referencia levantamiento 04
A21: Objeto de la opinión de valor | E21: Estimar el valor comercial del inmueble. | N21: Referencia revisión 05 / 06
A22: Propósito / uso previsto | N22: Superficies | Q22: Pendiente
A23: Enfoques aplicados | E23: =IF('9. Conciliación'!D11>0,"Mercado; ","")&IF('9. Conciliación'!D12>0,"Ingresos; ","")&IF('9. Conciliación'!D13>0,"Físico","") | N23: Diferencias y efecto en valor
A24: =IF(Q19="No realizada","Inspección no realizada","Fecha de inspección") -> Fecha de inspección | N24: Destinatario / derechos valorados
A25: Fecha de emisión | N25: Revisión jurídica | Q25: Pendiente
A26: Vigencia (válida hasta) | N26: Condiciones y efecto jurídico
A27: Tipo de valor | E27: Valor comercial / de mercado
A28: Moneda | E28: Pesos mexicanos (MXN) | N28: Estado de las bases | Q28: =IF(Q12="Cancelada","Operación cancelada",IF(OR(Q11<>"Venta",Q12="Cambio de operación"),"Replantear el alcance",IF(OR(Q9="",E10="",E12="",E13="",E15="",E17="",E22="",E29="",E33="",Q20="",Q21="",Q24="",Q14=""),"Completar identidad y alcance",IF(OR(NOT(ISNUMBER(Q10)),NOT(ISNUMBER(E25)),NOT(ISNUMBER(E26))),"Completar fechas",IF(OR(Q10<=0,E25<Q10,E26<E25),"Revisar fechas o vigencia",IF(AND(Q19<>"Realizada",Q19<>"No realizada"),"Definir inspección",IF(AND(Q19="Realizada",OR(NOT(ISNUMBER(E24)),E24<=0,E24>Q10)),"Revisar fecha de inspección",IF(OR(Q25="",Q25="Pendiente",Q25="No compatible"),"Resolver revisión jurídica",IF(AND(Q25="Condicionada",Q26=""),"Explicar condición jurídica",IF(OR(Q22="",Q22="Pendiente",AND(Q22="Discrepancia resuelta",Q23="")),"Conciliar superficies",IF(AND(Q13<>"Terreno",Q13<>"Construcción",Q13<>"Privativa"),"Definir base de mercado",IF('4. Inmueble'!Q24<>"Bases completas",'4. Inmueble'!Q24,"Bases completas")))))))))))) -> Completar identidad y alcance
A29: Alcance y condiciones limitantes
A31: DE LA INMOBILIARIA (EMISOR)
A32: Empresa inmobiliaria | E32: Fortius Real Estate & Investments
A33: Asesor que emite la opinión
A34: Contacto (correo / teléfono) | E34: Tel. +52 664 406 6999 | fortiusinmuebles.com
A36: DOCUMENTOS QUE SE TUVIERON A LA VISTA
A43: NOTA / ALCANCE DE LA OPINIÓN
A44: Opinión comercial orientativa. No sustituye un avalúo requerido por una autoridad, institución financiera o contrato. La revisión de campos no certifica la veracidad de las fuentes.

Sheet 3. Urbanas
I2: ="Opinión de valor comercial"&IF('2. Antecedentes'!$Q$9<>"",CHAR(10)&"Folio "&'2. Antecedentes'!$Q$9,"") -> Opinión de valor comercial
A7: 3. CARACTERÍSTICAS URBANAS DE LA ZONA
A9: ENTORNO
A10: Clasificación de la zona
A13: Uso del suelo (zonificación)
A14: Índice de saturación de la zona
A15: Dinámica de oferta y demanda
A16: Uso predominante (vivienda, mixto, etc.)
A18: SERVICIOS Y EQUIPAMIENTO URBANO
A19: Servicios públicos disponibles
A24: INFRAESTRUCTURA Y EQUIPAMIENTO CERCANO
A25: Escuelas / centros educativos
A26: Comercios y abasto
... A35: UBICACIÓN GEOGRÁFICA
A36: Latitud | G36: Longitud
A37: Altitud (msnm) | G37: Orientación
A39: CROQUIS DE LOCALIZACIÓN / MAPA (inserte la imagen de ubicación)

Sheet 4. Inmueble
I2: ="Opinión de valor comercial"&IF('2. Antecedentes'!$Q$9<>"",CHAR(10)&"Folio "&'2. Antecedentes'!$Q$9,"") -> Opinión de valor comercial
A7: 4. CARACTERÍSTICAS DEL INMUEBLE | N7: SUPERFICIES Y FUENTES (captura)
A9: TERRENO | N9: Origen terreno
A10: Superficie del terreno | G10: Frente (m) | N10: Fuente del terreno
A11: Indiviso (%) | G11: Sup. lote tipo (m²) | N11: Origen construcción
A12: Forma / configuración | G12: Topografía | N12: Fuente construcción
A13: Medidas y colindancias | N13: Área privativa (m²)
N14: Fuente área privativa
A16: Servidumbres y restricciones | N16: Superficie base de mercado | Q16: =IF('2. Antecedentes'!Q13="Terreno",IF(ISNUMBER(D10),D10,""),IF('2. Antecedentes'!Q13="Construcción",IF(ISNUMBER(D19),D19,""),IF('2. Antecedentes'!Q13="Privativa",IF(ISNUMBER(Q13),Q13,""),"")))
A18: CONSTRUCCIÓN | N18: Documento y fecha de edad
A19: Superficie construida | G19: Niveles | N19: Áreas inaccesibles / límites
A20: Recámaras | G20: Baños | N20: Origen datos físicos
A21: Estacionamientos | G21: Edad (años)
A22: Estado de conservación | G22: Calidad del proyecto | N22: Terreno atribuible revisado
A23: Descripción de la propiedad
N24: Estado de superficies | Q24: =IF(OR(NOT(ISNUMBER(Q16)),Q16<=0),"Falta superficie base",IF(AND('2. Antecedentes'!Q13="Terreno",OR(Q9="",Q10="",Q22<>"Revisado")),"Revisar terreno y derechos",IF(AND('2. Antecedentes'!Q13="Construcción",OR(Q11="",Q12="")),"Falta fuente construcción",IF(AND('2. Antecedentes'!Q13="Privativa",Q14=""),"Falta fuente privativa","Bases completas")))) -> Falta superficie base
A29: TIPOS DE CONSTRUCCIÓN
A30: Clave | C30: Tipo | D30: Uso | G30: Estado 1–6 | H30: Edad | I30: V. útil | J30: V. rest. | K30: Sup. m²
A36: ELEMENTOS DE LA CONSTRUCCIÓN (acabados e instalaciones)
A37: Cimentación
A38: Estructura
A39: Muros
A40: Entrepisos y losas
A41: Azoteas
A42: Aplanados y acabados
A43: Pisos
A44: Carpintería / herrería
A45: Instalación hidrosanitaria
A46: Instalación eléctrica
A47: Instalaciones especiales

Sheet 5. Comp. Terreno
I2: ="Opinión de valor comercial"&IF('2. Antecedentes'!$Q$9<>"",CHAR(10)&"Folio "&'2. Antecedentes'!$Q$9,"") -> Opinión de valor comercial
A7: 5. ENFOQUE COMPARATIVO DE MERCADO: TERRENOS | N7: EVIDENCIA DE COMPARABLES (captura)
A8: Comparables de lotes/terrenos en la zona, homologados a valor unitario por metro cuadrado. | N8: Tipo de precios a comparar
A9: COMPARABLES DE MERCADO (ofertas / operaciones recientes)
A10: No. | B10: Ubicación / referencia | D10: Base m² | E10: Precio MXN | F10: $/m² | G10: Fzona | H10: Fubic. | I10: Fsup. | J10: Fneg. | K10: F. res. | L10: $/m² hom. | N10: Comparable T1 (fila 11 de la tabla)
A11: 1 | E11: =IF(AND(ISNUMBER(Q18),Q18>0),Q18*IF(Q17="USD",'2. Antecedentes'!$Q$16,1),"") | F11: =IF(ISNUMBER(E11),E11/D11,"") | K11: =IF(ISNUMBER(E11),PRODUCT(G11:J11),"") | L11: =IF(AND(ISNUMBER(F11),ISNUMBER(K11)),F11*K11,"") | N11: Selección | Q11: Pendiente
A12: 2 | E12: =IF(AND(ISNUMBER(Q37),Q37>0),Q37*IF(Q36="USD",'2. Antecedentes'!$Q$16,1),"") | F12: =IF(ISNUMBER(E12),E12/D12,"") | K12: =IF(ISNUMBER(E12),PRODUCT(G12:J12),"") | L12: =IF(AND(ISNUMBER(F12),ISNUMBER(K12)),F12*K12,"") | N12: ID único del inmueble
A13: 3 | E13: =IF(AND(ISNUMBER(Q56),Q56>0),Q56*IF(Q55="USD",'2. Antecedentes'!$Q$16,1),"") | F13: =IF(ISNUMBER(E13),E13/D13,"") | K13: =IF(ISNUMBER(E13),PRODUCT(G13:J13),"") | L13: =IF(AND(ISNUMBER(F13),ISNUMBER(K13)),F13*K13,"") | N13: URL o referencia de evidencia
A14: 4 | E14: =IF(AND(ISNUMBER(Q75),Q75>0),Q75*IF(Q74="USD",'2. Antecedentes'!$Q$16,1),"") | F14: =IF(ISNUMBER(E14),E14/D14,"") | K14: =IF(ISNUMBER(E14),PRODUCT(G14:J14),"") | L14: =IF(AND(ISNUMBER(F14),ISNUMBER(K14)),F14*K14,"") | N14: Fecha de consulta
A15: 5 | E15: =IF(AND(ISNUMBER(Q94),Q94>0),Q94*IF(Q93="USD",'2. Antecedentes'!$Q$16,1),"") | F15: =IF(ISNUMBER(E15),E15/D15,"") | K15: =IF(ISNUMBER(E15),PRODUCT(G15:J15),"") | L15: =IF(AND(ISNUMBER(F15),ISNUMBER(K15)),F15*K15,"") | N15: Fecha del precio
A16: Valor unitario homologado medio ($/m²) | L16: =IF(COUNT(L11:L15)>=3,AVERAGE(L11:L15),"") | N16: Tipo de precio
A17: Dispersión de la muestra homologada: desviación estándar ($/m²) y coeficiente de variación | K17: =IF(AND(ISNUMBER(L16),COUNT(L11:L15)>1),STDEV(L11:L15),"") | L17: =IF(ISNUMBER(K17),K17/L16,"") | N17: Moneda
A18: RESULTADO DEL ENFOQUE | N18: Precio original sin IVA
A19: Sup. m² | D19: =IF(ISNUMBER('4. Inmueble'!D10),'4. Inmueble'!D10,"") | G19: Valor unitario terreno ($/m²) | J19: =IF(L16="","",L16) | N19: Fuente / base de superficie
A20: Factor adicional | D20: 1 | G20: Motivo del factor (si es distinto de 1) | N20: Justificación Fzona
A21: VALOR DE MERCADO DEL TERRENO ($) | J21: =IF(AND(ISNUMBER(D19),D19>0,ISNUMBER(J19)),D19*J19*IF(ISNUMBER(D20),D20,1),"") | N21: Justificación Fubic. / conservación
N22: Justificación Fsuperficie
A23: CRITERIOS DE SELECCIÓN Y AJUSTE DE COMPARABLES | N23: Justificación Fnegociación
N24: Razón de selección / exclusión
N25: Estado de esta fuente | Q25: =IF(Q11="Excluir",IF(Q24="","Explicar exclusión","Excluido"),IF(Q11<>"Incluir","Pendiente",IF(OR(B11="",Q12="",Q13="",Q19="",Q20="",Q21="",Q22="",Q23="",Q24=""),"Completar fuentes y ajustes",IF(OR(NOT(ISNUMBER(Q14)),NOT(ISNUMBER(Q15))),"Faltan fechas",IF(OR(Q14<=0,Q15<=0,Q14>'2. Antecedentes'!$E$25,Q15>'2. Antecedentes'!$Q$10),"Revisar fechas",IF(OR($Q$8="",Q16<>$Q$8),"No mezclar tipos de precio",IF(OR(AND(Q30="Incluir",OR(Q31=Q12,Q32=Q13)),AND(Q49="Incluir",OR(Q50=Q12,Q51=Q13)),AND(Q68="Incluir",OR(Q69=Q12,Q70=Q13)),AND(Q87="Incluir",OR(Q88=Q12,Q89=Q13))),"Fuente duplicada",IF(OR(NOT(ISNUMBER(D11)),D11<=0,NOT(ISNUMBER(Q18)),Q18<=0),"Falta precio o superficie",IF(AND(Q17<>"MXN",Q17<>"USD"),"Falta moneda",IF(AND(Q17="USD",OR(NOT(ISNUMBER('2. Antecedentes'!$Q$16)),'2. Antecedentes'!$Q$16<=0,NOT(ISNUMBER('2. Antecedentes'!$Q$17)),'2. Antecedentes'!$Q$17<=0,'2. Antecedentes'!$Q$17>'2. Antecedentes'!$Q$10,'2. Antecedentes'!$Q$18="")),"Falta conversión USD",IF(OR(COUNT(G11:J11)<>4,MIN(G11:J11)<=0),"Completar factores","Incluido"))))))))))) -> Pendiente
N27: =IF(ISNUMBER(L16),"Fuentes completas: "&COUNT(L11:L15)&". Revisar pertinencia y dispersión.","Pendiente: mínimo 3 fuentes completas y ninguna seleccionada con errores.") -> Pendiente: mínimo 3 fuentes completas y ninguna seleccionada con errores.
N29: Comparable T2 (fila 12 de la tabla)
N30: Selección | Q30: Pendiente
A31: Un factor igual a 1 indica que no se aplicó ajuste. Todo factor distinto de 1 se justifica en la ficha del comparable y no debe duplicar el efecto de otro factor. | N31: ID único del inmueble
N32: URL o referencia de evidencia
A33: FUENTES DE LOS COMPARABLES | N33: Fecha de consulta
A34: ID | C34: Referencia / URL | I34: Fecha precio | N34: Fecha del precio
A35: T1 | C35: =IF(Q13="","",Q13) | I35: =IF(Q15="","",Q15) | N35: Tipo de precio
A36: T2 | C36: =IF(Q32="","",Q32) | I36: =IF(Q34="","",Q34) | N36: Moneda
A37: T3 | C37: =IF(Q51="","",Q51) | I37: =IF(Q53="","",Q53) | N37: Precio original sin IVA
A38: T4 | C38: =IF(Q70="","",Q70) | I38: =IF(Q72="","",Q72) | N38: Fuente / base de superficie
A39: T5 | C39: =IF(Q89="","",Q89) | I39: =IF(Q91="","",Q91) | N39: Justificación Fzona
N40: Justificación Fubic. / conservación
N41: Justificación Fsuperficie
N42: Justificación Fnegociación
N43: Razón de selección / exclusión
N44: Estado de esta fuente | Q44: =IF(Q30="Excluir",IF(Q43="","Explicar exclusión","Excluido"),IF(Q30<>"Incluir","Pendiente",IF(OR(B12="",Q31="",Q32="",Q38="",Q39="",Q40="",Q41="",Q42="",Q43=""),"Completar fuentes y ajustes",IF(OR(NOT(ISNUMBER(Q33)),NOT(ISNUMBER(Q34))),"Faltan fechas",IF(OR(Q33<=0,Q34<=0,Q33>'2. Antecedentes'!$E$25,Q34>'2. Antecedentes'!$Q$10),"Revisar fechas",IF(OR($Q$8="",Q35<>$Q$8),"No mezclar tipos de precio",IF(OR(AND(Q11="Incluir",OR(Q12=Q31,Q13=Q32)),AND(Q49="Incluir",OR(Q50=Q31,Q51=Q32)),AND(Q68="Incluir",OR(Q69=Q31,Q70=Q32)),AND(Q87="Incluir",OR(Q88=Q31,Q89=Q32))),"Fuente duplicada",IF(OR(NOT(ISNUMBER(D12)),D12<=0,NOT(ISNUMBER(Q37)),Q37<=0),"Falta precio o superficie",IF(AND(Q36<>"MXN",Q36<>"USD"),"Falta moneda",IF(AND(Q36="USD",OR(NOT(ISNUMBER('2. Antecedentes'!$Q$16)),'2. Antecedentes'!$Q$16<=0,NOT(ISNUMBER('2. Antecedentes'!$Q$17)),'2. Antecedentes'!$Q$17<=0,'2. Antecedentes'!$Q$17>'2. Antecedentes'!$Q$10,'2. Antecedentes'!$Q$18="")),"Falta conversión USD",IF(OR(COUNT(G12:J12)<>4,MIN(G12:J12)<=0),"Completar factores","Incluido"))))))))))) -> Pendiente
N48: Comparable T3 (fila 13 de la tabla)
N49: Selección | Q49: Pendiente
N50: ID único del inmueble
...

Sheet 6. Comp. Constr.
I2: ="Opinión de valor comercial"&IF('2. Antecedentes'!$Q$9<>"",CHAR(10)&"Folio "&'2. Antecedentes'!$Q$9,"") -> Opinión de valor comercial
A7: 6. ENFOQUE COMPARATIVO DE MERCADO: INMUEBLES CONSTRUIDOS | N7: EVIDENCIA DE COMPARABLES (captura)
A8: Precio total del inmueble por m² de construcción o área privativa. El resultado ya incluye los derechos sobre el terreno. | N8: Tipo de precios a comparar
A9: COMPARABLES DE MERCADO (ofertas / operaciones recientes)
A10: No. | B10: Ubicación / referencia | D10: Base m² | E10: Precio MXN | F10: $/m² | G10: Fzona | H10: Fconserv. | I10: Fsup. | J10: Fneg. | K10: F. res. | L10: $/m² hom. | N10: Comparable C1 (fila 11 de la tabla)
A11: 1 | E11: =IF(AND(ISNUMBER(Q18),Q18>0),Q18*IF(Q17="USD",'2. Antecedentes'!$Q$16,1),"") | F11: =IF(ISNUMBER(E11),E11/D11,"") | K11: =IF(ISNUMBER(E11),PRODUCT(G11:J11),"") | L11: =IF(AND(ISNUMBER(F11),ISNUMBER(K11)),F11*K11,"") | N11: Selección | Q11: Pendiente
A12: 2 | E12: =IF(AND(ISNUMBER(Q37),Q37>0),Q37*IF(Q36="USD",'2. Antecedentes'!$Q$16,1),"") | F12: =IF(ISNUMBER(E12),E12/D12,"") | K12: =IF(ISNUMBER(E12),PRODUCT(G12:J12),"") | L12: =IF(AND(ISNUMBER(F12),ISNUMBER(K12)),F12*K12,"") | N12: ID único del inmueble
A13: 3 | E13: =IF(AND(ISNUMBER(Q56),Q56>0),Q56*IF(Q55="USD",'2. Antecedentes'!$Q$16,1),"") | F13: =IF(ISNUMBER(E13),E13/D13,"") | K13: =IF(ISNUMBER(E13),PRODUCT(G13:J13),"") | L13: =IF(AND(ISNUMBER(F13),ISNUMBER(K13)),F13*K13,"") | N13: URL o referencia de evidencia
A14: 4 | E14: =IF(AND(ISNUMBER(Q75),Q75>0),Q75*IF(Q74="USD",'2. Antecedentes'!$Q$16,1),"") | F14: =IF(ISNUMBER(E14),E14/D14,"") | K14: =IF(ISNUMBER(E14),PRODUCT(G14:J14),"") | L14: =IF(AND(ISNUMBER(F14),ISNUMBER(K14)),F14*K14,"") | N14: Fecha de consulta
A15: 5 | E15: =IF(AND(ISNUMBER(Q94),Q94>0),Q94*IF(Q93="USD",'2. Antecedentes'!$Q$16,1),"") | F15: =IF(ISNUMBER(E15),E15/D15,"") | K15: =IF(ISNUMBER(E15),PRODUCT(G15:J15),"") | L15: =IF(AND(ISNUMBER(F15),ISNUMBER(K15)),F15*K15,"") | N15: Fecha del precio
A16: Valor unitario homologado medio ($/m²) | L16: =IF(COUNT(L11:L15)>=3,AVERAGE(L11:L15),"") | N16: Tipo de precio
A17: Dispersión de la muestra homologada: desviación estándar ($/m²) y coeficiente de variación | K17: =IF(AND(ISNUMBER(L16),COUNT(L11:L15)>1),STDEV(L11:L15),"") | L17: =IF(ISNUMBER(K17),K17/L16,"") | N17: Moneda
A18: RESULTADO DEL ENFOQUE | N18: Precio original sin IVA
A19: Base del sujeto m² | D19: =IF(ISNUMBER('4. Inmueble'!Q16),'4. Inmueble'!Q16,"") | G19: Valor unitario MXN/m² | J19: =IF(L16="","",L16) | N19: Fuente / base de superficie
A20: Factor adicional | D20: 1 | G20: Motivo del factor (si es distinto de 1) | N20: Justificación Fzona
A21: VALOR POR ENFOQUE COMPARATIVO DE MERCADO ($) | J21: =IF(AND(ISNUMBER(D19),D19>0,ISNUMBER(J19),'2. Antecedentes'!Q13<>"Terreno"),D19*J19*IF(ISNUMBER(D20),D20,1),"") | N21: Justificación Fubic. / conservación
N22: Justificación Fsuperficie
A23: CRITERIOS DE SELECCIÓN Y AJUSTE DE COMPARABLES | N23: Justificación Fnegociación
N24: Razón de selección / exclusión
N25: Estado de esta fuente | Q25: =IF(Q11="Excluir",IF(Q24="","Explicar exclusión","Excluido"),IF(Q11<>"Incluir","Pendiente",IF(OR(B11="",Q12="",Q13="",Q19="",Q20="",Q21="",Q22="",Q23="",Q24=""),"Completar fuentes y ajustes",IF(OR(NOT(ISNUMBER(Q14)),NOT(ISNUMBER(Q15))),"Faltan fechas",IF(OR(Q14<=0,Q15<=0,Q14>'2. Antecedentes'!$E$25,Q15>'2. Antecedentes'!$Q$10),"Revisar fechas",IF(OR($Q$8="",Q16<>$Q$8),"No mezclar tipos de precio",IF(OR(AND(Q30="Incluir",OR(Q31=Q12,Q32=Q13)),AND(Q49="Incluir",OR(Q50=Q12,Q51=Q13)),AND(Q68="Incluir",OR(Q69=Q12,Q70=Q13)),AND(Q87="Incluir",OR(Q88=Q12,Q89=Q13))),"Fuente duplicada",IF(OR(NOT(ISNUMBER(D11)),D11<=0,NOT(ISNUMBER(Q18)),Q18<=0),"Falta precio o superficie",IF(AND(Q17<>"MXN",Q17<>"USD"),"Falta moneda",IF(AND(Q17="USD",OR(NOT(ISNUMBER('2. Antecedentes'!$Q$16)),'2. Antecedentes'!$Q$16<=0,NOT(ISNUMBER('2. Antecedentes'!$Q$17)),'2. Antecedentes'!$Q$17<=0,'2. Antecedentes'!$Q$17>'2. Antecedentes'!$Q$10,'2. Antecedentes'!$Q$18="")),"Falta conversión USD",IF(OR(COUNT(G11:J11)<>4,MIN(G11:J11)<=0),"Completar factores","Incluido"))))))))))) -> Pendiente
N27: =IF(ISNUMBER(L16),"Fuentes completas: "&COUNT(L11:L15)&". Revisar pertinencia y dispersión.","Pendiente: mínimo 3 fuentes completas y ninguna seleccionada con errores.") -> Pendiente: mínimo 3 fuentes completas y ninguna seleccionada con errores.
N29: Comparable C2 (fila 12 de la tabla)
N30: Selección | Q30: Pendiente
A31: Un factor igual a 1 indica que no se aplicó ajuste. Todo factor distinto de 1 se justifica en la ficha del comparable y no debe duplicar el efecto de otro factor. | N31: ID único del inmueble
N32: URL o referencia de evidencia
A33: FUENTES DE LOS COMPARABLES | N33: Fecha de consulta
A34: ID | C34: Referencia / URL | I34: Fecha precio | N34: Fecha del precio
A35: C1 | C35: =IF(Q13="","",Q13) | I35: =IF(Q15="","",Q15) | N35: Tipo de precio
A36: C2 | C36: =IF(Q32="","",Q32) | I36: =IF(Q34="","",Q34) | N36: Moneda
A37: C3 | C37: =IF(Q51="","",Q51) | I37: =IF(Q53="","",Q53) | N37: Precio original sin IVA
A38: C4 | C38: =IF(Q70="","",Q70) | I38: =IF(Q72="","",Q72) | N38: Fuente / base de superficie
A39: C5 | C39: =IF(Q89="","",Q89) | I39: =IF(Q91="","",Q91) | N39: Justificación Fzona
N40: Justificación Fubic. / conservación
N41: Justificación Fsuperficie
N42: Justificación Fnegociación
N43: Razón de selección / exclusión
N44: Estado de esta fuente | Q44: =IF(Q30="Excluir",IF(Q43="","Explicar exclusión","Excluido"),IF(Q30<>"Incluir","Pendiente",IF(OR(B12="",Q31="",Q32="",Q38="",Q39="",Q40="",Q41="",Q42="",Q43=""),"Completar fuentes y ajustes",IF(OR(NOT(ISNUMBER(Q33)),NOT(ISNUMBER(Q34))),"Faltan fechas",IF(OR(Q33<=0,Q34<=0,Q33>'2. Antecedentes'!$E$25,Q34>'2. Antecedentes'!$Q$10),"Revisar fechas",IF(OR($Q$8="",Q35<>$Q$8),"No mezclar tipos de precio",IF(OR(AND(Q11="Incluir",OR(Q12=Q31,Q13=Q32)),AND(Q49="Incluir",OR(Q50=Q31,Q51=Q32)),AND(Q68="Incluir",OR(Q69=Q31,Q70=Q32)),AND(Q87="Incluir",OR(Q88=Q31,Q89=Q32))),"Fuente duplicada",IF(OR(NOT(ISNUMBER(D12)),D12<=0,NOT(ISNUMBER(Q37)),Q37<=0),"Falta precio o superficie",IF(AND(Q36<>"MXN",Q36<>"USD"),"Falta moneda",IF(AND(Q36="USD",OR(NOT(ISNUMBER('2. Antecedentes'!$Q$16)),'2. Antecedentes'!$Q$16<=0,NOT(ISNUMBER('2. Antecedentes'!$Q$17)),'2. Antecedentes'!$Q$17<=0,'2. Antecedentes'!$Q$17>'2. Antecedentes'!$Q$10,'2. Antecedentes'!$Q$18="")),"Falta conversión USD",IF(OR(COUNT(G12:J12)<>4,MIN(G12:J12)<=0),"Completar factores","Incluido"))))))))))) -> Pendiente
N48: Comparable C3 (fila 13 de la tabla)
N49: Selección | Q49: Pendiente
N50: ID único del inmueble
...

Sheet 7. Ingresos
I2: ="Opinión de valor comercial"&IF('2. Antecedentes'!$Q$9<>"",CHAR(10)&"Folio "&'2. Antecedentes'!$Q$9,"") -> Opinión de valor comercial
A7: 7. ENFOQUE DE INGRESOS (CAPITALIZACIÓN DE RENTAS) | N7: EVIDENCIA DE COMPARABLES (captura)
A8: Estima el valor a partir de la renta de mercado del inmueble, sus deducciones y la tasa de capitalización. | N8: Tipo de precios a comparar
A10: COMPARABLES DE RENTA ($/m² por mes) | N10: Comparable R1 (fila 12 de la tabla)
A11: No. | B11: Ubicación / referencia | D11: Base m² | E11: Renta MXN/mes | F11: $/m²/mes | G11: Fzona | H11: Fconserv. | I11: Fsup. | J11: Fneg. | K11: F. res. | L11: $/m² hom. | N11: Selección | Q11: Pendiente
A12: 1 | E12: =IF(AND(ISNUMBER(Q18),Q18>0),Q18*IF(Q17="USD",'2. Antecedentes'!$Q$16,1),"") | F12: =IF(ISNUMBER(E12),E12/D12,"") | K12: =IF(ISNUMBER(E12),PRODUCT(G12:J12),"") | L12: =IF(AND(ISNUMBER(F12),ISNUMBER(K12)),F12*K12,"") | N12: ID único del inmueble
A13: 2 | E13: =IF(AND(ISNUMBER(Q37),Q37>0),Q37*IF(Q36="USD",'2. Antecedentes'!$Q$16,1),"") | F13: =IF(ISNUMBER(E13),E13/D13,"") | K13: =IF(ISNUMBER(E13),PRODUCT(G13:J13),"") | L13: =IF(AND(ISNUMBER(F13),ISNUMBER(K13)),F13*K13,"") | N13: URL o referencia de evidencia
A14: 3 | E14: =IF(AND(ISNUMBER(Q56),Q56>0),Q56*IF(Q55="USD",'2. Antecedentes'!$Q$16,1),"") | F14: =IF(ISNUMBER(E14),E14/D14,"") | K14: =IF(ISNUMBER(E14),PRODUCT(G14:J14),"") | L14: =IF(AND(ISNUMBER(F14),ISNUMBER(K14)),F14*K14,"") | N14: Fecha de consulta
A15: 4 | E15: =IF(AND(ISNUMBER(Q75),Q75>0),Q75*IF(Q74="USD",'2. Antecedentes'!$Q$16,1),"") | F15: =IF(ISNUMBER(E15),E15/D15,"") | K15: =IF(ISNUMBER(E15),PRODUCT(G15:J15),"") | L15: =IF(AND(ISNUMBER(F15),ISNUMBER(K15)),F15*K15,"") | N15: Fecha del precio
A16: 5 | E16: =IF(AND(ISNUMBER(Q94),Q94>0),Q94*IF(Q93="USD",'2. Antecedentes'!$Q$16,1),"") | F16: =IF(ISNUMBER(E16),E16/D16,"") | K16: =IF(ISNUMBER(E16),PRODUCT(G16:J16),"") | L16: =IF(AND(ISNUMBER(F16),ISNUMBER(K16)),F16*K16,"") | N16: Tipo de precio
A17: Renta unitaria homologada media ($/m²/mes) | L17: =IF(COUNT(L12:L16)>=3,AVERAGE(L12:L16),"") | N17: Moneda
A18: Renta mensual: superficie base del sujeto × renta unitaria media | L18: =IF(AND(ISNUMBER('4. Inmueble'!Q16),'4. Inmueble'!Q16>0,ISNUMBER(L17)),'4. Inmueble'!Q16*L17,"") | N18: Precio original sin IVA
A19: INGRESO BRUTO | N19: Fuente / base de superficie
A20: Renta mensual de mercado | H20: =IF(L18="","",L18) | N20: Justificación Fzona
A21: Renta bruta anual (× 12) | H21: =IF(ISNUMBER(H20),H20*12,"") | N21: Justificación Fubic. / conservación
N22: Justificación Fsuperficie
A23: DEDUCCIONES | N23: Justificación Fnegociación
A24: Vacancía y cobranza (%) | N24: Razón de selección / exclusión
A25: Pérdida por vacancía | H25: =IF(AND(ISNUMBER(H21),ISNUMBER(H24),H24>=0,H24<1),H21*H24,"") | N25: Estado de esta fuente | Q25: =IF(Q11="Excluir",IF(Q24="","Explicar exclusión","Excluido"),IF(Q11<>"Incluir","Pendiente",IF(OR(B12="",Q12="",Q13="",Q19="",Q20="",Q21="",Q22="",Q23="",Q24=""),"Completar fuentes y ajustes",IF(OR(NOT(ISNUMBER(Q14)),NOT(ISNUMBER(Q15))),"Faltan fechas",IF(OR(Q14<=0,Q15<=0,Q14>'2. Antecedentes'!$E$25,Q15>'2. Antecedentes'!$Q$10),"Revisar fechas",IF(OR($Q$8="",Q16<>$Q$8),"No mezclar tipos de precio",IF(OR(AND(Q30="Incluir",OR(Q31=Q12,Q32=Q13)),AND(Q49="Incluir",OR(Q50=Q12,Q51=Q13)),AND(Q68="Incluir",OR(Q69=Q12,Q70=Q13)),AND(Q87="Incluir",OR(Q88=Q12,Q89=Q13))),"Fuente duplicada",IF(OR(NOT(ISNUMBER(D12)),D12<=0,NOT(ISNUMBER(Q18)),Q18<=0),"Falta precio o superficie",IF(AND(Q17<>"MXN",Q17<>"USD"),"Falta moneda",IF(AND(Q17="USD",OR(NOT(ISNUMBER('2. Antecedentes'!$Q$16)),'2. Antecedentes'!$Q$16<=0,NOT(ISNUMBER('2. Antecedentes'!$Q$17)),'2. Antecedentes'!$Q$17<=0,'2. Antecedentes'!$Q$17>'2. Antecedentes'!$Q$10,'2. Antecedentes'!$Q$18="")),"Falta conversión USD",IF(OR(COUNT(G12:J12)<>4,MIN(G12:J12)<=0),"Completar factores","Incluido"))))))))))) -> Pendiente
A26: Renta bruta efectiva | H26: =IF(AND(ISNUMBER(H21),ISNUMBER(H25)),H21-H25,"")
A27: Gastos de operación (%) | N27: =IF(ISNUMBER(L17),"Fuentes completas: "&COUNT(L12:L16)&". Revisar pertinencia y dispersión.","Pendiente: mínimo 3 fuentes completas y ninguna seleccionada con errores.") -> Pendiente: mínimo 3 fuentes completas y ninguna seleccionada con errores.
A28: Gastos de operación ($) | H28: =IF(AND(ISNUMBER(H26),ISNUMBER(H27),H27>=0,H27<1),H26*H27,"")
N29: Comparable R2 (fila 13 de la tabla)
A30: CAPITALIZACIÓN | N30: Selección | Q30: Pendiente
A31: Ingreso neto operativo (NOI) | H31: =IF(AND(ISNUMBER(H26),ISNUMBER(H28)),H26-H28,"") | N31: ID único del inmueble
A32: Tasa de capitalización (%) | N32: URL o referencia de evidencia
N33: Fecha de consulta
A34: VALOR POR ENFOQUE DE INGRESOS ($) | H34: =IF(AND(ISNUMBER(H31),ISNUMBER(H32),H32>0,H32<1),H31/H32,"") | N34: Fecha del precio
A35: SUSTENTO DE VACANCÍA, GASTOS Y TASA NETA | N35: Tipo de precio
N36: Moneda
N37: Precio original sin IVA
N38: Fuente / base de superficie
N39: Justificación Fzona
N40: Justificación Fubic. / conservación
A41: FUENTES DE LOS COMPARABLES | N41: Justificación Fsuperficie
A42: ID | C42: Referencia / URL | I42: Fecha precio | N42: Justificación Fnegociación
A43: R1 | C43: =IF(Q13="","",Q13) | I43: =IF(Q15="","",Q15) | N43: Razón de selección / exclusión
A44: R2 | C44: =IF(Q32="","",Q32) | I44: =IF(Q34="","",Q34) | N44: Estado de esta fuente | Q44: =IF(Q30="Excluir",IF(Q43="","Explicar exclusión","Excluido"),IF(Q30<>"Incluir","Pendiente",IF(OR(B13="",Q31="",Q32="",Q38="",Q39="",Q40="",Q41="",Q42="",Q43=""),"Completar fuentes y ajustes",IF(OR(NOT(ISNUMBER(Q33)),NOT(ISNUMBER(Q34))),"Faltan fechas",IF(OR(Q33<=0,Q34<=0,Q33>'2. Antecedentes'!$E$25,Q34>'2. Antecedentes'!$Q$10),"Revisar fechas",IF(OR($Q$8="",Q35<>$Q$8),"No mezclar tipos de precio",IF(OR(AND(Q11="Incluir",OR(Q12=Q31,Q13=Q32)),AND(Q49="Incluir",OR(Q50=Q31,Q51=Q32)),AND(Q68="Incluir",OR(Q69=Q31,Q70=Q32)),AND(Q87="Incluir",OR(Q88=Q31,Q89=Q32))),"Fuente duplicada",IF(OR(NOT(ISNUMBER(D13)),D13<=0,NOT(ISNUMBER(Q37)),Q37<=0),"Falta precio o superficie",IF(AND(Q36<>"MXN",Q36<>"USD"),"Falta moneda",IF(AND(Q36="USD",OR(NOT(ISNUMBER('2. Antecedentes'!$Q$16)),'2. Antecedentes'!$Q$16<=0,NOT(ISNUMBER('2. Antecedentes'!$Q$17)),'2. Antecedentes'!$Q$17<=0,'2. Antecedentes'!$Q$17>'2. Antecedentes'!$Q$10,'2. Antecedentes'!$Q$18="")),"Falta conversión USD",IF(OR(COUNT(G13:J13)<>4,MIN(G13:J13)<=0),"Completar factores","Incluido"))))))))))) -> Pendiente
A45: R3 | C45: =IF(Q51="","",Q51) | I45: =IF(Q53="","",Q53)
A46: R4 | C46: =IF(Q70="","",Q70) | I46: =IF(Q72="","",Q72)
...

Sheet 8. Físico
I2: ="Opinión de valor comercial"&IF('2. Antecedentes'!$Q$9<>"",CHAR(10)&"Folio "&'2. Antecedentes'!$Q$9,"") -> Opinión de valor comercial
A7: 8. ENFOQUE FÍSICO (VALOR NETO DE REPOSICIÓN) | N7: FUENTES DEL ENFOQUE FÍSICO
A9: A) VALOR DEL TERRENO | N9: Costo nuevo: fuente, fecha y ajuste
A10: Superficie (m²) | D10: =IF('4. Inmueble'!D10="","",'4. Inmueble'!D10) | G10: Valor unitario ($/m²) | J10: =IF('5. Comp. Terreno'!J19="","",'5. Comp. Terreno'!J19) | N10: Edad y vida útil: fuente
A11: Factor aplicado (sección 5) | D11: =IF(ISNUMBER('5. Comp. Terreno'!D20),'5. Comp. Terreno'!D20,1) -> 1 | G11: SUBTOTAL (A) | J11: =IF(ISNUMBER('5. Comp. Terreno'!J21),'5. Comp. Terreno'!J21,"") | N11: Factor terreno: justificación
N12: Obras complementarias
A13: B) CONSTRUCCIONES: VALOR NETO DE REPOSICIÓN | N13: Fuentes de obras / exclusiones
A14: Tipo de construcción | C14: Sup. m² | D14: VRN $/m² | E14: Edad (años) | F14: Vida útil (años) | G14: Estado 1–6 | H14: Coef. Ross | I14: Coef. Heidecke | J14: Factor neto | K14: VNR neto $/m² | L14: Valor parcial $ | N14: Integridad del inventario | Q14: Pendiente
A15: =IF('4. Inmueble'!A31="","",'4. Inmueble'!A31) | C15: =IF('4. Inmueble'!K31="","",'4. Inmueble'!K31) | E15: =IF('4. Inmueble'!H31="","",'4. Inmueble'!H31) | F15: =IF('4. Inmueble'!I31="","",'4. Inmueble'!I31) | G15: =IF('4. Inmueble'!G31="","",'4. Inmueble'!G31) | H15: =IF(AND(ISNUMBER(E15),E15>=0,ISNUMBER(F15),F15>0,E15<=F15),0.5*((E15/F15)+(E15/F15)^2),"") | I15: =IF(AND(ISNUMBER(G15),COUNTIF($N$37:$N$42,G15)=1),VLOOKUP(G15,$N$37:$O$42,2,FALSE),"") | J15: =IF(AND(ISNUMBER(H15),ISNUMBER(I15)),(1-H15)*(1-I15),"") | K15: =IF(AND(ISNUMBER(D15),D15>0,ISNUMBER(J15)),D15*J15,"") | L15: =IF(AND(A15<>"",ISNUMBER(C15),C15>0,ISNUMBER(K15)),C15*K15,"") | N15: Método pertinente | Q15: Pendiente
A16: =IF('4. Inmueble'!A32="","",'4. Inmueble'!A32) | C16: =IF('4. Inmueble'!K32="","",'4. Inmueble'!K32) | E16: =IF('4. Inmueble'!H32="","",'4. Inmueble'!H32) | F16: =IF('4. Inmueble'!I32="","",'4. Inmueble'!I32) | G16: =IF('4. Inmueble'!G32="","",'4. Inmueble'!G32) | H16: =IF(AND(ISNUMBER(E16),E16>=0,ISNUMBER(F16),F16>0,E16<=F16),0.5*((E16/F16)+(E16/F16)^2),"") | I16: =IF(AND(ISNUMBER(G16),COUNTIF($N$37:$N$42,G16)=1),VLOOKUP(G16,$N$37:$O$42,2,FALSE),"") | J16: =IF(AND(ISNUMBER(H16),ISNUMBER(I16)),(1-H16)*(1-I16),"") | K16: =IF(AND(ISNUMBER(D16),D16>0,ISNUMBER(J16)),D16*J16,"") | L16: =IF(AND(A16<>"",ISNUMBER(C16),C16>0,ISNUMBER(K16)),C16*K16,"") | N16: Supuestos de depreciación
A17: =IF('4. Inmueble'!A33="","",'4. Inmueble'!A33) | C17: =IF('4. Inmueble'!K33="","",'4. Inmueble'!K33) | E17: =IF('4. Inmueble'!H33="","",'4. Inmueble'!H33) | F17: =IF('4. Inmueble'!I33="","",'4. Inmueble'!I33) | G17: =IF('4. Inmueble'!G33="","",'4. Inmueble'!G33) | H17: =IF(AND(ISNUMBER(E17),E17>=0,ISNUMBER(F17),F17>0,E17<=F17),0.5*((E17/F17)+(E17/F17)^2),"") | I17: =IF(AND(ISNUMBER(G17),COUNTIF($N$37:$N$42,G17)=1),VLOOKUP(G17,$N$37:$O$42,2,FALSE),"") | J17: =IF(AND(ISNUMBER(H17),ISNUMBER(I17)),(1-H17)*(1-I17),"") | K17: =IF(AND(ISNUMBER(D17),D17>0,ISNUMBER(J17)),D17*J17,"") | L17: =IF(AND(A17<>"",ISNUMBER(C17),C17>0,ISNUMBER(K17)),C17*K17,"")
A18: =IF('4. Inmueble'!A34="","",'4. Inmueble'!A34) | C18: =IF('4. Inmueble'!K34="","",'4. Inmueble'!K34) | E18: =IF('4. Inmueble'!H34="","",'4. Inmueble'!H34) | F18: =IF('4. Inmueble'!I34="","",'4. Inmueble'!I34) | G18: =IF('4. Inmueble'!G34="","",'4. Inmueble'!G34) | H18: =IF(AND(ISNUMBER(E18),E18>=0,ISNUMBER(F18),F18>0,E18<=F18),0.5*((E18/F18)+(E18/F18)^2),"") | I18: =IF(AND(ISNUMBER(G18),COUNTIF($N$37:$N$42,G18)=1),VLOOKUP(G18,$N$37:$O$42,2,FALSE),"") | J18: =IF(AND(ISNUMBER(H18),ISNUMBER(I18)),(1-H18)*(1-I18),"") | K18: =IF(AND(ISNUMBER(D18),D18>0,ISNUMBER(J18)),D18*J18,"") | L18: =IF(AND(A18<>"",ISNUMBER(C18),C18>0,ISNUMBER(K18)),C18*K18,"")
A19: SUBTOTAL (B) | L19: =IF(COUNT(L15:L18)>0,SUM(L15:L18),"")
A21: C) INSTALACIONES ESPECIALES, ELEMENTOS ACCESORIOS Y OBRAS COMPLEMENTARIAS
A22: Concepto | E22: Unidad | G22: Cant. | H22: VRN $ | J22: F. cons. | K22: Valor parcial $
K23: =IF(AND(A23<>"",E23<>"",ISNUMBER(G23),G23>0,ISNUMBER(H23),H23>0,ISNUMBER(J23),J23>=0,J23<=1),G23*H23*J23,"")
K24: =IF(AND(A24<>"",E24<>"",ISNUMBER(G24),G24>0,ISNUMBER(H24),H24>0,ISNUMBER(J24),J24>=0,J24<=1),G24*H24*J24,"")
K25: =IF(AND(A25<>"",E25<>"",ISNUMBER(G25),G25>0,ISNUMBER(H25),H25>0,ISNUMBER(J25),J25>=0,J25<=1),G25*H25*J25,"")
A26: SUBTOTAL (C) | K26: =SUM(K23:K25)
A28: VALOR FÍSICO = A + B + C ($) | J28: =IF(AND(ISNUMBER(J11),ISNUMBER(L19),ISNUMBER(K26)),J11+L19+K26,"")
A30: DEPRECIACIÓN ROSS-HEIDECKE: PARÁMETROS
A31: Coef. Ross (edad) = ½ × [ (Edad ÷ Vida útil) + (Edad ÷ Vida útil)² ]
A32: Factor neto de depreciación = (1 − Coef. Ross) × (1 − Coef. Heidecke)
A33: VNR neto ($/m²) = VRN × Factor neto; Valor parcial = Superficie × VNR neto
A35: El costo nuevo, la edad, la vida útil y el estado de conservación se documentan por componente con su fuente. Esta variante no considera valor de rescate ni indirectos; los accesorios ya incluidos en el costo nuevo no se vuelven a contar. | N35: Tabla de conservación (Heidecke)
N36: Estado | O36: Coef. | P36: Descripción del estado de conservación
N37: 1 | O37: 0 | P37: Óptimo / nuevo (Heidecke 1)
N38: 2 | O38: 0.0252 | P38: Bueno, reparaciones menores (Heidecke 2)
N39: 3 | O39: 0.181 | P39: Regular, reparaciones simples (Heidecke 3)
N40: 4 | O40: 0.526 | P40: Malo, reparaciones importantes (Heidecke 4)
N41: 5 | O41: 0.752 | P41: Muy malo, reparaciones mayores (Heidecke 4.5)
A42: FUENTES Y SUPUESTOS ADOPTADOS | N42: 6 | O42: 1 | P42: Ruinoso, sin valor de construcción (Heidecke 5)
A43: =IF(Q9="","Por documentar: costo nuevo, edad, vida útil y método de depreciación.","Costo: "&Q9&CHAR(10)&"Edad y vida útil: "&Q10&CHAR(10)&"Método y supuestos: "&Q16) -> Por documentar: costo nuevo, edad, vida útil y método de depreciación.

Sheet 9. Conciliación
I2: ="Opinión de valor comercial"&IF('2. Antecedentes'!$Q$9<>"",CHAR(10)&"Folio "&'2. Antecedentes'!$Q$9,"") -> Opinión de valor comercial
A7: 9. CONCILIACIÓN DE VALOR Y JUSTIFICACIÓN | N7: CIERRE DE LA OPINIÓN (captura)
A9: PONDERACIÓN DE ENFOQUES | N9: Redondear a múltiplos de
A10: Enfoque de valor | D10: Peso | F10: Valor indicado | I10: Valor ponderado | N10: Revisión del responsable | Q10: Pendiente
A11: Comparativo de mercado | F11: =IF('2. Antecedentes'!Q13="Terreno",IF(ISNUMBER('5. Comp. Terreno'!J21),'5. Comp. Terreno'!J21,""),IF(ISNUMBER('6. Comp. Constr.'!J21),'6. Comp. Constr.'!J21,"")) | I11: =IF(AND(ISNUMBER(D11),D11>=0,D11<=1),IF(D11=0,0,IF(AND(ISNUMBER(F11),F11>0),D11*F11,"")),"") | N11: Fecha de revisión
A12: Ingresos (capitalización) | F12: =IF('7. Ingresos'!H34="","",'7. Ingresos'!H34) | I12: =IF(AND(ISNUMBER(D12),D12>=0,D12<=1),IF(D12=0,0,IF(AND(ISNUMBER(F12),F12>0),D12*F12,"")),"") | N12: Indicador I14 revisado
A13: Físico (neto de reposición) | F13: =IF('8. Físico'!J28="","",'8. Físico'!J28) | I13: =IF(AND(ISNUMBER(D13),D13>=0,D13<=1),IF(D13=0,0,IF(AND(ISNUMBER(F13),F13>0),D13*F13,"")),"") | N13: Versión revisada
A14: Suma | D14: =IF(COUNT(D11:D13)=3,SUM(D11:D13),"") | I14: =IF(AND(COUNT(D11:D13)=3,ABS(SUM(D11:D13)-1)<0.000001,MIN(D11:D13)>=0,MAX(D11:D13)<=1,COUNT(I11:I13)=3),SUM(I11:I13),"")
N15: Estado de la conclusión | Q15: =IF('2. Antecedentes'!Q28<>"Bases completas",'2. Antecedentes'!Q28,IF(NOT(ISNUMBER(I14)),"Revisar pesos y enfoques",IF(OR(NOT(ISNUMBER(Q9)),Q9<=0),"Definir redondeo",IF(A19="","Redactar justificación",IF(OR(Q10<>"Revisada",NOT(ISNUMBER(Q11)),Q11<'2. Antecedentes'!Q10,Q11>'2. Antecedentes'!E25),"Completar revisión",IF(OR(NOT(ISNUMBER(Q12)),ABS(Q12-I14)>0.01,Q13<>'2. Antecedentes'!Q14),"Actualizar revisión","Revisada")))))) -> Completar identidad y alcance
A16: VALOR COMERCIAL CONCLUIDO (MXN) | I16: =IF(ISNUMBER(I14),ROUND(I14/IF(AND(ISNUMBER(Q9),Q9>0),Q9,1),0)*IF(AND(ISNUMBER(Q9),Q9>0),Q9,1),"")
A17: =IF(Q26="","","("&Q26&")")
A18: JUSTIFICACIÓN DE LA OPINIÓN DE VALOR | N18: Valor en letra (cálculo auxiliar, no editar)
N19: Parte entera | Q19: =IF(ISNUMBER(I16),INT(I16),0) -> 0
N20: Millones | Q20: =INT(Q19/1000000) -> 0
N21: Miles | Q21: =INT(MOD(Q19,1000000)/1000) -> 0
N22: Unidades | Q22: =MOD(Q19,1000) -> 0
N23: Texto millones | Q23: =IF(Q20=0,"",IF(Q20=100,"cien",CHOOSE(INT(Q20/100)+1,"","ciento ","doscientos ","trescientos ","cuatrocientos ","quinientos ","seiscientos ","setecientos ","ochocientos ","novecientos ")&IF(MOD(Q20,100)<30,CHOOSE(MOD(Q20,100)+1,"","uno","dos","tres","cuatro","cinco","seis","siete","ocho","nueve","diez","once","doce","trece","catorce","quince","dieciséis","diecisiete","dieciocho","diecinueve","veinte","veintiuno","veintidós","veintitrés","veinticuatro","veinticinco","veintiséis","veintisiete","veintiocho","veintinueve"),CHOOSE(INT(MOD(Q20,100)/10)-2,"treinta","cuarenta","cincuenta","sesenta","setenta","ochenta","noventa")&IF(MOD(Q20,10)>0," y "&CHOOSE(MOD(Q20,10),"uno","dos","tres","cuatro","cinco","seis","siete","ocho","nueve"),""))))
N24: Texto miles | Q24: =IF(Q21=0,"",IF(Q21=100,"cien",CHOOSE(INT(Q21/100)+1,"","ciento ","doscientos ","trescientos ","cuatrocientos ","quinientos ","seiscientos ","setecientos ","ochocientos ","novecientos ")&IF(MOD(Q21,100)<30,CHOOSE(MOD(Q21,100)+1,"","uno","dos","tres","cuatro","cinco","seis","siete","ocho","nueve","diez","once","doce","trece","catorce","quince","dieciséis","diecisiete","dieciocho","diecinueve","veinte","veintiuno","veintidós","veintitrés","veinticuatro","veinticinco","veintiséis","veintisiete","veintiocho","veintinueve"),CHOOSE(INT(MOD(Q21,100)/10)-2,"treinta","cuarenta","cincuenta","sesenta","setenta","ochenta","noventa")&IF(MOD(Q21,10)>0," y "&CHOOSE(MOD(Q21,10),"uno","dos","tres","cuatro","cinco","seis","siete","ocho","nueve"),""))))
N25: Texto unidades | Q25: =IF(Q22=0,"",IF(Q22=100,"cien",CHOOSE(INT(Q22/100)+1,"","ciento ","doscientos ","trescientos ","cuatrocientos ","quinientos ","seiscientos ","setecientos ","ochocientos ","novecientos ")&IF(MOD(Q22,100)<30,CHOOSE(MOD(Q22,100)+1,"","uno","dos","tres","cuatro","cinco","seis","siete","ocho","nueve","diez","once","doce","trece","catorce","quince","dieciséis","diecisiete","dieciocho","diecinueve","veinte","veintiuno","veintidós","veintitrés","veinticuatro","veinticinco","veintiséis","veintisiete","veintiocho","veintinueve"),CHOOSE(INT(MOD(Q22,100)/10)-2,"treinta","cuarenta","cincuenta","sesenta","setenta","ochenta","noventa")&IF(MOD(Q22,10)>0," y "&CHOOSE(MOD(Q22,10),"uno","dos","tres","cuatro","cinco","seis","siete","ocho","nueve"),""))))
A26: SUPUESTOS, CONDICIONES LIMITANTES Y VIGENCIA | N26: Valor en letra | Q26: =IF(NOT(ISNUMBER(I16)),"",UPPER(TRIM(IF(Q20=1,"un millón ",IF(Q20>1,SUBSTITUTE(SUBSTITUTE(Q23,"veintiuno","veintiún"),"uno","un")&" millones ",""))&IF(Q21=1,"mil ",IF(Q21>1,SUBSTITUTE(SUBSTITUTE(Q24,"veintiuno","veintiún"),"uno","un")&" mil ",""))&IF(AND(Q22=0,Q21=0,Q20>0),"de ","")&SUBSTITUTE(SUBSTITUTE(Q25,"veintiuno","veintiún"),"uno","un")))&" PESOS "&TEXT(ROUND((I16-Q19)*100,0),"00")&"/100 M.N.")
A27: 1. La opinión distingue datos documentados, observados y declarados. Las fuentes y reservas se identifican en el informe. 2. Los precios corresponden a sus fechas registradas; oferta y cierre no son equivalentes. El mercado puede cambiar. 3. No se certifica cumplimiento normativo ni condición de sistemas ocultos; se declaran el alcance de inspección y los límites técnicos. 4. Las condiciones jurídicas y su efecto se describen en antecedentes; no se suponen resueltas. 5. La fecha de revisión se fija para el caso. Cambios del inmueble, operación o mercado requieren actualizar la opinión. 6. Es una referencia comercial, no garantía de venta ni sustituto de un avalúo exigido por autoridad, banco o contrato.
U30: =SUBSTITUTE(SUBSTITUTE("x","x",""),"","")
A33: VALIDACIÓN
A34: Asesor que emite la opinión | D34: =IF('2. Antecedentes'!E33="","",'2. Antecedentes'!E33) | G34: Empresa inmobiliaria | I34: =IF('2. Antecedentes'!E32="","",'2. Antecedentes'!E32) -> Fortius Real Estate & Investments
A35: Fecha de emisión | D35: =IF('2. Antecedentes'!E25="","",'2. Antecedentes'!E25) | G35: Vigente hasta | I35: =IF('2. Antecedentes'!E26="","",'2. Antecedentes'!E26)
D37: =IF('2. Antecedentes'!E33="","",'2. Antecedentes'!E33)
D38: Asesor que emite la opinión
D39: =IF('2. Antecedentes'!E32="","",'2. Antecedentes'!E32) -> Fortius Real Estate & Investments
A41: VIGENCIA DE LA OPINIÓN
A42: =IF(ISNUMBER('2. Antecedentes'!E26),"Esta opinión es válida hasta el "&TEXT('2. Antecedentes'!E26,"dd \d\e mmmm \d\e yyyy")&", salvo cambios en el inmueble, la operación o las condiciones de mercado.","")

Sheet 10. Fotografías
I2: ="Opinión de valor comercial"&IF('2. Antecedentes'!$Q$9<>"",CHAR(10)&"Folio "&'2. Antecedentes'!$Q$9,"") -> Opinión de valor comercial
A7: 10. REPORTE FOTOGRÁFICO DEL INMUEBLE
A8: Fotografías del inmueble y su entorno, con pie que identifica la vista y la fecha de la visita.
A10: FOTOGRAFÍA 1 | G10: FOTOGRAFÍA 2
A18: Pie | G18: Pie
A20: FOTOGRAFÍA 3 | G20: FOTOGRAFÍA 4
A28: Pie | G28: Pie
A30: FOTOGRAFÍA 5 | G30: FOTOGRAFÍA 6
A38: Pie | G38: Pie
A40: FOTOGRAFÍA 7 | G40: FOTOGRAFÍA 8
A48: Pie | G48: Pie
